INFO:root:2017-09-26 21:29:08:现在开始测试:test_case1
INFO:root:2017-09-26 21:29:08:测试有异常:Traceback (most recent call last):
  File "C:\study\selenium\code\studyDemo\log_warp_demo.py", line 13, in wraps
    test_case_func(*args, **keywords)
  File "C:\study\selenium\code\studyDemo\log_warp_demo.py", line 22, in test_case1
    driver.find_element_by_id('kw11')
  File "C:\Users\fo\AppData\Local\Programs\Python\Python36-32\lib\site-packages\selenium\webdriver\remote\webdriver.py", line 285, in find_element_by_id
    return self.find_element(by=By.ID, value=id_)
  File "C:\Users\fo\AppData\Local\Programs\Python\Python36-32\lib\site-packages\selenium\webdriver\remote\webdriver.py", line 787, in find_element
    'value': value})['value']
  File "C:\Users\fo\AppData\Local\Programs\Python\Python36-32\lib\site-packages\selenium\webdriver\remote\webdriver.py", line 252, in execute
    self.error_handler.check_response(response)
  File "C:\Users\fo\AppData\Local\Programs\Python\Python36-32\lib\site-packages\selenium\webdriver\remote\errorhandler.py", line 194, in check_response
    raise exception_class(message, screen, stacktrace)
selenium.common.exceptions.NoSuchElementException: Message: Unable to locate element: [id="kw11"]


